[2024-04-30T10:47:27.907+0000] {task_context_logger.py:104} ERROR - Executor reports task instance <TaskInstance: dog.get_dog_api scheduled__2024-04-30T04:40:00+00:00 [queued]> finished (failed) although the task says it's queued. (Info: None) Was the task killed externally?
